{"uuid": "053157bc-7a4e-4385-99e2-6bcf430f9860", "children": ["d8c7416e-db13-45df-a30c-884c367142d2"], "befores": [{"name": "api_client", "status": "broken", "statusDetails": {"message": "requests.exceptions.ConnectionError: HTTPConnectionPool(host='127.0.0.1', port=3000): Max retries exceeded with url: /reg (Caused by NewConnectionError('<urllib3.connection.HTTPConnection object at 0x10a984a90>: Failed to establish a new connection: [Errno 61] Connection refused'))\n", "trace": "  File \"/usr/local/lib/python3.7/site-packages/pluggy/callers.py\", line 187, in _multicall\n    res = hook_impl.function(*args)\n  File \"/usr/local/lib/python3.7/site-packages/_pytest/fixtures.py\", line 964, in pytest_fixture_setup\n    result = call_fixture_func(fixturefunc, request, kwargs)\n  File \"/usr/local/lib/python3.7/site-packages/_pytest/fixtures.py\", line 792, in call_fixture_func\n    res = fixturefunc(**kwargs)\n  File \"/Users/renata/PycharmProjects/final_progect/tests/test_api.py\", line 20, in api_client\n    return ApiClient(username, password, email)\n  File \"/Users/renata/PycharmProjects/final_progect/api/api_client.py\", line 17, in __init__\n    'submit': 'Registration'\n  File \"/usr/local/lib/python3.7/site-packages/requests/sessions.py\", line 578, in post\n    return self.request('POST', url, data=data, json=json, **kwargs)\n  File \"/usr/local/lib/python3.7/site-packages/requests/sessions.py\", line 530, in request\n    resp = self.send(prep, **send_kwargs)\n  File \"/usr/local/lib/python3.7/site-packages/requests/sessions.py\", line 643, in send\n    r = adapter.send(request, **kwargs)\n  File \"/usr/local/lib/python3.7/site-packages/requests/adapters.py\", line 516, in send\n    raise ConnectionError(e, request=request)\n"}, "start": 1590610023247, "stop": 1590610023250}], "start": 1590610023247, "stop": 1590610023498}