{"uuid": "9c4fed32-29ec-44f3-8926-e357fd08773a", "children": ["e07343c9-f0a2-4ec2-b0c4-52af183ac278"], "befores": [{"name": "api_client", "status": "broken", "statusDetails": {"message": "requests.exceptions.ConnectionError: HTTPConnectionPool(host='127.0.0.1', port=3000): Max retries exceeded with url: /reg (Caused by NewConnectionError('<urllib3.connection.HTTPConnection object at 0x112814bd0>: Failed to establish a new connection: [Errno 61] Connection refused'))\n", "trace": "  File \"/usr/local/lib/python3.7/site-packages/pluggy/callers.py\", line 187, in _multicall\n    res = hook_impl.function(*args)\n  File \"/usr/local/lib/python3.7/site-packages/_pytest/fixtures.py\", line 964, in pytest_fixture_setup\n    result = call_fixture_func(fixturefunc, request, kwargs)\n  File \"/usr/local/lib/python3.7/site-packages/_pytest/fixtures.py\", line 792, in call_fixture_func\n    res = fixturefunc(**kwargs)\n  File \"/Users/renata/PycharmProjects/final_progect/tests/test_api.py\", line 20, in api_client\n    return ApiClient(username, password, email)\n  File \"/Users/renata/PycharmProjects/final_progect/api/api_client.py\", line 17, in __init__\n    'submit': 'Registration'\n  File \"/usr/local/lib/python3.7/site-packages/requests/sessions.py\", line 578, in post\n    return self.request('POST', url, data=data, json=json, **kwargs)\n  File \"/usr/local/lib/python3.7/site-packages/requests/sessions.py\", line 530, in request\n    resp = self.send(prep, **send_kwargs)\n  File \"/usr/local/lib/python3.7/site-packages/requests/sessions.py\", line 643, in send\n    r = adapter.send(request, **kwargs)\n  File \"/usr/local/lib/python3.7/site-packages/requests/adapters.py\", line 516, in send\n    raise ConnectionError(e, request=request)\n"}, "start": 1590609036289, "stop": 1590609036292}], "start": 1590609036289, "stop": 1590609036986}